/root/.pm2/logs/iot-error.log last 15 lines:
1|iot      |
1|iot      | Exception in thread Thread-2611660:
1|iot      | Traceback (most recent call last):
1|iot      |   File "/usr/lib/python3.5/threading.py", line 914, in _bootstrap_inner
1|iot      |     self.run()
1|iot      |   File "/usr/lib/python3.5/threading.py", line 862, in run
1|iot      |     self._target(*self._args, **self._kwargs)
1|iot      |   File "/usr/local/lib/python3.5/dist-packages/engineio/client.py", line 671, in _write_loop
1|iot      |     self.queue.task_done()
1|iot      |   File "/usr/lib/python3.5/queue.py", line 68, in task_done
1|iot      |     raise ValueError('task_done() called too many times')
1|iot      | ValueError: task_done() called too many times
1|iot      |
1|iot      | packet queue is empty, aborting
1|iot      | packet queue is empty, aborting




1|iot      |   File "/usr/local/lib/python3.5/dist-packages/websocket/_core.py", line 253, in send
1|iot      |     return self.send_frame(frame)
1|iot      |   File "/usr/local/lib/python3.5/dist-packages/websocket/_core.py", line 279, in send_frame
1|iot      |     l = self._send(data)
1|iot      |   File "/usr/local/lib/python3.5/dist-packages/websocket/_core.py", line 449, in _send
1|iot      |     return send(self.sock, data)
1|iot      |   File "/usr/local/lib/python3.5/dist-packages/websocket/_socket.py", line 157, in send
1|iot      |     return _send()
1|iot      |   File "/usr/local/lib/python3.5/dist-packages/websocket/_socket.py", line 139, in _send
1|iot      |     return sock.send(data)
1|iot      |   File "/usr/lib/python3.5/ssl.py", line 871, in send
1|iot      |     return socket.send(self, data, flags)
1|iot      | BrokenPipeError: [Errno 32] Broken pipe
1|iot      |
1|iot      | packet queue is empty, aborting